DEBUG 2015-06-10 22:31:12,351: 	 Executing command: 'status'
DEBUG 2015-06-10 22:31:12,352: 	 Found CRAB cache file /afs/cern.ch/user/h/hardenbr/.crab3
ERROR 2015-06-10 22:31:12,352: 	 Error: crab3_phys14_qcd.py is not a valid CRAB project directory.
ERROR 2015-06-10 22:31:12,352: 	 Caught exception
Traceback (most recent call last):
  File "/cvmfs/cms.cern.ch/crab3/slc6_amd64_gcc481/cms/crabclient/3.3.1506/bin/crab", line 136, in <module>
    client()
  File "/cvmfs/cms.cern.ch/crab3/slc6_amd64_gcc481/cms/crabclient/3.3.1506/bin/crab", line 122, in __call__
    self.cmd = sub_cmd(self.logger, args[1:])
  File "/cvmfs/cms.cern.ch/crab3/slc6_amd64_gcc481/cms/crabclient/3.3.1506/lib/python2.6/site-packages/CRABClient/Commands/SubCommand.py", line 253, in __init__
    self.validateOptions()
  File "/cvmfs/cms.cern.ch/crab3/slc6_amd64_gcc481/cms/crabclient/3.3.1506/lib/python2.6/site-packages/CRABClient/Commands/status.py", line 731, in validateOptions
    SubCommand.validateOptions(self)
  File "/cvmfs/cms.cern.ch/crab3/slc6_amd64_gcc481/cms/crabclient/3.3.1506/lib/python2.6/site-packages/CRABClient/Commands/SubCommand.py", line 563, in validateOptions
    raise ConfigurationException(msg)
ConfigurationException: [91mError[0m: crab3_phys14_qcd.py is not a valid CRAB project directory.
DEBUG 2015-06-10 22:31:12,749: 	 Executing command: 'status'
DEBUG 2015-06-10 22:31:12,749: 	 Found CRAB cache file /afs/cern.ch/user/h/hardenbr/.crab3
ERROR 2015-06-10 22:31:12,749: 	 Error: crab3_spring15_qcd.py~ is not a valid CRAB project directory.
ERROR 2015-06-10 22:31:12,749: 	 Caught exception
Traceback (most recent call last):
  File "/cvmfs/cms.cern.ch/crab3/slc6_amd64_gcc481/cms/crabclient/3.3.1506/bin/crab", line 136, in <module>
    client()
  File "/cvmfs/cms.cern.ch/crab3/slc6_amd64_gcc481/cms/crabclient/3.3.1506/bin/crab", line 122, in __call__
    self.cmd = sub_cmd(self.logger, args[1:])
  File "/cvmfs/cms.cern.ch/crab3/slc6_amd64_gcc481/cms/crabclient/3.3.1506/lib/python2.6/site-packages/CRABClient/Commands/SubCommand.py", line 253, in __init__
    self.validateOptions()
  File "/cvmfs/cms.cern.ch/crab3/slc6_amd64_gcc481/cms/crabclient/3.3.1506/lib/python2.6/site-packages/CRABClient/Commands/status.py", line 731, in validateOptions
    SubCommand.validateOptions(self)
  File "/cvmfs/cms.cern.ch/crab3/slc6_amd64_gcc481/cms/crabclient/3.3.1506/lib/python2.6/site-packages/CRABClient/Commands/SubCommand.py", line 563, in validateOptions
    raise ConfigurationException(msg)
ConfigurationException: [91mError[0m: crab3_spring15_qcd.py~ is not a valid CRAB project directory.
DEBUG 2015-06-10 22:31:13,172: 	 Executing command: 'status'
DEBUG 2015-06-10 22:31:13,172: 	 Found CRAB cache file /afs/cern.ch/user/h/hardenbr/.crab3
ERROR 2015-06-10 22:31:13,172: 	 Error: crab3_phys14_qcd.pyc is not a valid CRAB project directory.
ERROR 2015-06-10 22:31:13,173: 	 Caught exception
Traceback (most recent call last):
  File "/cvmfs/cms.cern.ch/crab3/slc6_amd64_gcc481/cms/crabclient/3.3.1506/bin/crab", line 136, in <module>
    client()
  File "/cvmfs/cms.cern.ch/crab3/slc6_amd64_gcc481/cms/crabclient/3.3.1506/bin/crab", line 122, in __call__
    self.cmd = sub_cmd(self.logger, args[1:])
  File "/cvmfs/cms.cern.ch/crab3/slc6_amd64_gcc481/cms/crabclient/3.3.1506/lib/python2.6/site-packages/CRABClient/Commands/SubCommand.py", line 253, in __init__
    self.validateOptions()
  File "/cvmfs/cms.cern.ch/crab3/slc6_amd64_gcc481/cms/crabclient/3.3.1506/lib/python2.6/site-packages/CRABClient/Commands/status.py", line 731, in validateOptions
    SubCommand.validateOptions(self)
  File "/cvmfs/cms.cern.ch/crab3/slc6_amd64_gcc481/cms/crabclient/3.3.1506/lib/python2.6/site-packages/CRABClient/Commands/SubCommand.py", line 563, in validateOptions
    raise ConfigurationException(msg)
ConfigurationException: [91mError[0m: crab3_phys14_qcd.pyc is not a valid CRAB project directory.
DEBUG 2015-06-10 22:31:13,552: 	 Executing command: 'status'
DEBUG 2015-06-10 22:31:13,552: 	 Found CRAB cache file /afs/cern.ch/user/h/hardenbr/.crab3
ERROR 2015-06-10 22:31:13,553: 	 Error: crab3_spring15_qcd.pyc is not a valid CRAB project directory.
ERROR 2015-06-10 22:31:13,553: 	 Caught exception
Traceback (most recent call last):
  File "/cvmfs/cms.cern.ch/crab3/slc6_amd64_gcc481/cms/crabclient/3.3.1506/bin/crab", line 136, in <module>
    client()
  File "/cvmfs/cms.cern.ch/crab3/slc6_amd64_gcc481/cms/crabclient/3.3.1506/bin/crab", line 122, in __call__
    self.cmd = sub_cmd(self.logger, args[1:])
  File "/cvmfs/cms.cern.ch/crab3/slc6_amd64_gcc481/cms/crabclient/3.3.1506/lib/python2.6/site-packages/CRABClient/Commands/SubCommand.py", line 253, in __init__
    self.validateOptions()
  File "/cvmfs/cms.cern.ch/crab3/slc6_amd64_gcc481/cms/crabclient/3.3.1506/lib/python2.6/site-packages/CRABClient/Commands/status.py", line 731, in validateOptions
    SubCommand.validateOptions(self)
  File "/cvmfs/cms.cern.ch/crab3/slc6_amd64_gcc481/cms/crabclient/3.3.1506/lib/python2.6/site-packages/CRABClient/Commands/SubCommand.py", line 563, in validateOptions
    raise ConfigurationException(msg)
ConfigurationException: [91mError[0m: crab3_spring15_qcd.pyc is not a valid CRAB project directory.
DEBUG 2015-07-16 12:46:12,327: 	 Executing command: 'submit'
DEBUG 2015-07-16 12:46:12,337: 	 Found CRAB cache file /afs/cern.ch/user/h/hardenbr/.crab3
DEBUG 2015-07-16 12:46:12,351: 	 Checking credentials
DEBUG 2015-07-16 12:46:12,351: 	 Found proxy file /tmp/x509up_u56682
DEBUG 2015-07-16 12:46:12,351: 	 Getting proxy life time left
DEBUG 2015-07-16 12:46:12,959: 	 Executing : 
 command : voms-proxy-info -file /tmp/x509up_u56682 -timeleft
 output : 43055

 error: 
 retcode : 0
DEBUG 2015-07-16 12:46:13,466: 	 Executing : 
 command : voms-proxy-info -file /tmp/x509up_u56682 -actimeleft
 output : 43054

 error: 
 retcode : 0
DEBUG 2015-07-16 12:46:13,466: 	 Proxy valid for 11:57:35 hours
DEBUG 2015-07-16 12:46:13,467: 	 Will use CRAB Analysis plugin (i.e. will run an analysis job type).
DEBUG 2015-07-19 21:36:21,510: 	 Executing command: 'submit'
DEBUG 2015-07-19 21:36:21,529: 	 Found CRAB cache file /afs/cern.ch/user/h/hardenbr/.crab3
DEBUG 2015-07-19 21:36:21,567: 	 Checking credentials
DEBUG 2015-07-19 21:36:21,567: 	 Found proxy file /tmp/x509up_u56682
DEBUG 2015-07-19 21:36:21,567: 	 Getting proxy life time left
DEBUG 2015-07-19 21:36:22,071: 	 Executing : 
 command : voms-proxy-info -file /tmp/x509up_u56682 -timeleft
 output : 43148

 error: 
 retcode : 0
DEBUG 2015-07-19 21:36:22,477: 	 Executing : 
 command : voms-proxy-info -file /tmp/x509up_u56682 -actimeleft
 output : 43147

 error: 
 retcode : 0
DEBUG 2015-07-19 21:36:22,477: 	 Proxy valid for 11:59:08 hours
DEBUG 2015-07-19 21:36:22,478: 	 Will use CRAB Analysis plugin (i.e. will run an analysis job type).
DEBUG 2015-07-19 23:18:22,943: 	 Executing command: 'submit'
DEBUG 2015-07-19 23:18:22,956: 	 Found CRAB cache file /afs/cern.ch/user/h/hardenbr/.crab3
DEBUG 2015-07-19 23:18:22,973: 	 Checking credentials
DEBUG 2015-07-19 23:18:22,975: 	 Found proxy file /tmp/x509up_u56682
DEBUG 2015-07-19 23:18:22,975: 	 Getting proxy life time left
DEBUG 2015-07-19 23:18:23,583: 	 Executing : 
 command : voms-proxy-info -file /tmp/x509up_u56682 -timeleft
 output : 42927

 error: 
 retcode : 0
DEBUG 2015-07-19 23:18:24,095: 	 Executing : 
 command : voms-proxy-info -file /tmp/x509up_u56682 -actimeleft
 output : 42926

 error: 
 retcode : 0
DEBUG 2015-07-19 23:18:24,096: 	 Proxy valid for 11:55:27 hours
DEBUG 2015-07-19 23:18:24,096: 	 Will use CRAB Analysis plugin (i.e. will run an analysis job type).
DEBUG 2015-07-19 23:22:54,618: 	 Executing command: 'submit'
DEBUG 2015-07-19 23:22:54,626: 	 Found CRAB cache file /afs/cern.ch/user/h/hardenbr/.crab3
DEBUG 2015-07-19 23:22:54,637: 	 Checking credentials
DEBUG 2015-07-19 23:22:54,637: 	 Found proxy file /tmp/x509up_u56682
DEBUG 2015-07-19 23:22:54,637: 	 Getting proxy life time left
DEBUG 2015-07-19 23:22:55,147: 	 Executing : 
 command : voms-proxy-info -file /tmp/x509up_u56682 -timeleft
 output : 42655

 error: 
 retcode : 0
DEBUG 2015-07-19 23:22:55,653: 	 Executing : 
 command : voms-proxy-info -file /tmp/x509up_u56682 -actimeleft
 output : 42655

 error: 
 retcode : 0
DEBUG 2015-07-19 23:22:55,653: 	 Proxy valid for 11:50:55 hours
DEBUG 2015-07-19 23:22:55,654: 	 Will use CRAB Analysis plugin (i.e. will run an analysis job type).
DEBUG 2015-07-19 23:31:54,102: 	 Executing command: 'status'
DEBUG 2015-07-19 23:31:54,102: 	 Found CRAB cache file /afs/cern.ch/user/h/hardenbr/.crab3
ERROR 2015-07-19 23:31:54,103: 	 Error: CfiFile_cfi.py is not a valid CRAB project directory.
ERROR 2015-07-19 23:31:54,103: 	 Caught exception
Traceback (most recent call last):
  File "/cvmfs/cms.cern.ch/crab3/slc6_amd64_gcc481/cms/crabclient/3.3.1507-comp/bin/crab", line 133, in <module>
    client()
  File "/cvmfs/cms.cern.ch/crab3/slc6_amd64_gcc481/cms/crabclient/3.3.1507-comp/bin/crab", line 119, in __call__
    self.cmd = sub_cmd(self.logger, args[1:])
  File "/cvmfs/cms.cern.ch/crab3/slc6_amd64_gcc481/cms/crabclient/3.3.1507-comp/lib/python2.6/site-packages/CRABClient/Commands/SubCommand.py", line 253, in __init__
    self.validateOptions()
  File "/cvmfs/cms.cern.ch/crab3/slc6_amd64_gcc481/cms/crabclient/3.3.1507-comp/lib/python2.6/site-packages/CRABClient/Commands/status.py", line 731, in validateOptions
    SubCommand.validateOptions(self)
  File "/cvmfs/cms.cern.ch/crab3/slc6_amd64_gcc481/cms/crabclient/3.3.1507-comp/lib/python2.6/site-packages/CRABClient/Commands/SubCommand.py", line 563, in validateOptions
    raise ConfigurationException(msg)
ConfigurationException: [91mError[0m: CfiFile_cfi.py is not a valid CRAB project directory.
DEBUG 2015-07-19 23:31:54,534: 	 Executing command: 'status'
DEBUG 2015-07-19 23:31:54,535: 	 Found CRAB cache file /afs/cern.ch/user/h/hardenbr/.crab3
ERROR 2015-07-19 23:31:54,535: 	 Error: ConfFile_cfg.py is not a valid CRAB project directory.
ERROR 2015-07-19 23:31:54,535: 	 Caught exception
Traceback (most recent call last):
  File "/cvmfs/cms.cern.ch/crab3/slc6_amd64_gcc481/cms/crabclient/3.3.1507-comp/bin/crab", line 133, in <module>
    client()
  File "/cvmfs/cms.cern.ch/crab3/slc6_amd64_gcc481/cms/crabclient/3.3.1507-comp/bin/crab", line 119, in __call__
    self.cmd = sub_cmd(self.logger, args[1:])
  File "/cvmfs/cms.cern.ch/crab3/slc6_amd64_gcc481/cms/crabclient/3.3.1507-comp/lib/python2.6/site-packages/CRABClient/Commands/SubCommand.py", line 253, in __init__
    self.validateOptions()
  File "/cvmfs/cms.cern.ch/crab3/slc6_amd64_gcc481/cms/crabclient/3.3.1507-comp/lib/python2.6/site-packages/CRABClient/Commands/status.py", line 731, in validateOptions
    SubCommand.validateOptions(self)
  File "/cvmfs/cms.cern.ch/crab3/slc6_amd64_gcc481/cms/crabclient/3.3.1507-comp/lib/python2.6/site-packages/CRABClient/Commands/SubCommand.py", line 563, in validateOptions
    raise ConfigurationException(msg)
ConfigurationException: [91mError[0m: ConfFile_cfg.py is not a valid CRAB project directory.
DEBUG 2015-07-19 23:31:54,950: 	 Executing command: 'status'
DEBUG 2015-07-19 23:31:54,950: 	 Found CRAB cache file /afs/cern.ch/user/h/hardenbr/.crab3
ERROR 2015-07-19 23:31:54,951: 	 Error: QCD.txt is not a valid CRAB project directory.
ERROR 2015-07-19 23:31:54,951: 	 Caught exception
Traceback (most recent call last):
  File "/cvmfs/cms.cern.ch/crab3/slc6_amd64_gcc481/cms/crabclient/3.3.1507-comp/bin/crab", line 133, in <module>
    client()
  File "/cvmfs/cms.cern.ch/crab3/slc6_amd64_gcc481/cms/crabclient/3.3.1507-comp/bin/crab", line 119, in __call__
    self.cmd = sub_cmd(self.logger, args[1:])
  File "/cvmfs/cms.cern.ch/crab3/slc6_amd64_gcc481/cms/crabclient/3.3.1507-comp/lib/python2.6/site-packages/CRABClient/Commands/SubCommand.py", line 253, in __init__
    self.validateOptions()
  File "/cvmfs/cms.cern.ch/crab3/slc6_amd64_gcc481/cms/crabclient/3.3.1507-comp/lib/python2.6/site-packages/CRABClient/Commands/status.py", line 731, in validateOptions
    SubCommand.validateOptions(self)
  File "/cvmfs/cms.cern.ch/crab3/slc6_amd64_gcc481/cms/crabclient/3.3.1507-comp/lib/python2.6/site-packages/CRABClient/Commands/SubCommand.py", line 563, in validateOptions
    raise ConfigurationException(msg)
ConfigurationException: [91mError[0m: QCD.txt is not a valid CRAB project directory.
DEBUG 2015-07-19 23:31:55,420: 	 Executing command: 'status'
DEBUG 2015-07-19 23:31:55,420: 	 Found CRAB cache file /afs/cern.ch/user/h/hardenbr/.crab3
ERROR 2015-07-19 23:31:55,421: 	 Error: __init__.py is not a valid CRAB project directory.
ERROR 2015-07-19 23:31:55,421: 	 Caught exception
Traceback (most recent call last):
  File "/cvmfs/cms.cern.ch/crab3/slc6_amd64_gcc481/cms/crabclient/3.3.1507-comp/bin/crab", line 133, in <module>
    client()
  File "/cvmfs/cms.cern.ch/crab3/slc6_amd64_gcc481/cms/crabclient/3.3.1507-comp/bin/crab", line 119, in __call__
    self.cmd = sub_cmd(self.logger, args[1:])
  File "/cvmfs/cms.cern.ch/crab3/slc6_amd64_gcc481/cms/crabclient/3.3.1507-comp/lib/python2.6/site-packages/CRABClient/Commands/SubCommand.py", line 253, in __init__
    self.validateOptions()
  File "/cvmfs/cms.cern.ch/crab3/slc6_amd64_gcc481/cms/crabclient/3.3.1507-comp/lib/python2.6/site-packages/CRABClient/Commands/status.py", line 731, in validateOptions
    SubCommand.validateOptions(self)
  File "/cvmfs/cms.cern.ch/crab3/slc6_amd64_gcc481/cms/crabclient/3.3.1507-comp/lib/python2.6/site-packages/CRABClient/Commands/SubCommand.py", line 563, in validateOptions
    raise ConfigurationException(msg)
ConfigurationException: [91mError[0m: __init__.py is not a valid CRAB project directory.
DEBUG 2015-07-19 23:31:55,866: 	 Executing command: 'status'
DEBUG 2015-07-19 23:31:55,867: 	 Found CRAB cache file /afs/cern.ch/user/h/hardenbr/.crab3
ERROR 2015-07-19 23:31:55,867: 	 Error: analyze_cfg.py is not a valid CRAB project directory.
ERROR 2015-07-19 23:31:55,867: 	 Caught exception
Traceback (most recent call last):
  File "/cvmfs/cms.cern.ch/crab3/slc6_amd64_gcc481/cms/crabclient/3.3.1507-comp/bin/crab", line 133, in <module>
    client()
  File "/cvmfs/cms.cern.ch/crab3/slc6_amd64_gcc481/cms/crabclient/3.3.1507-comp/bin/crab", line 119, in __call__
    self.cmd = sub_cmd(self.logger, args[1:])
  File "/cvmfs/cms.cern.ch/crab3/slc6_amd64_gcc481/cms/crabclient/3.3.1507-comp/lib/python2.6/site-packages/CRABClient/Commands/SubCommand.py", line 253, in __init__
    self.validateOptions()
  File "/cvmfs/cms.cern.ch/crab3/slc6_amd64_gcc481/cms/crabclient/3.3.1507-comp/lib/python2.6/site-packages/CRABClient/Commands/status.py", line 731, in validateOptions
    SubCommand.validateOptions(self)
  File "/cvmfs/cms.cern.ch/crab3/slc6_amd64_gcc481/cms/crabclient/3.3.1507-comp/lib/python2.6/site-packages/CRABClient/Commands/SubCommand.py", line 563, in validateOptions
    raise ConfigurationException(msg)
ConfigurationException: [91mError[0m: analyze_cfg.py is not a valid CRAB project directory.
DEBUG 2015-07-19 23:31:56,273: 	 Executing command: 'status'
DEBUG 2015-07-19 23:31:56,273: 	 Found CRAB cache file /afs/cern.ch/user/h/hardenbr/.crab3
ERROR 2015-07-19 23:31:56,273: 	 Error: crab.log is not a valid CRAB project directory.
ERROR 2015-07-19 23:31:56,274: 	 Caught exception
Traceback (most recent call last):
  File "/cvmfs/cms.cern.ch/crab3/slc6_amd64_gcc481/cms/crabclient/3.3.1507-comp/bin/crab", line 133, in <module>
    client()
  File "/cvmfs/cms.cern.ch/crab3/slc6_amd64_gcc481/cms/crabclient/3.3.1507-comp/bin/crab", line 119, in __call__
    self.cmd = sub_cmd(self.logger, args[1:])
  File "/cvmfs/cms.cern.ch/crab3/slc6_amd64_gcc481/cms/crabclient/3.3.1507-comp/lib/python2.6/site-packages/CRABClient/Commands/SubCommand.py", line 253, in __init__
    self.validateOptions()
  File "/cvmfs/cms.cern.ch/crab3/slc6_amd64_gcc481/cms/crabclient/3.3.1507-comp/lib/python2.6/site-packages/CRABClient/Commands/status.py", line 731, in validateOptions
    SubCommand.validateOptions(self)
  File "/cvmfs/cms.cern.ch/crab3/slc6_amd64_gcc481/cms/crabclient/3.3.1507-comp/lib/python2.6/site-packages/CRABClient/Commands/SubCommand.py", line 563, in validateOptions
    raise ConfigurationException(msg)
ConfigurationException: [91mError[0m: crab.log is not a valid CRAB project directory.
DEBUG 2015-07-19 23:31:56,728: 	 Executing command: 'status'
DEBUG 2015-07-19 23:31:56,728: 	 Found CRAB cache file /afs/cern.ch/user/h/hardenbr/.crab3
ERROR 2015-07-19 23:31:56,729: 	 Error: crab3_phys14_qcd.py is not a valid CRAB project directory.
ERROR 2015-07-19 23:31:56,729: 	 Caught exception
Traceback (most recent call last):
  File "/cvmfs/cms.cern.ch/crab3/slc6_amd64_gcc481/cms/crabclient/3.3.1507-comp/bin/crab", line 133, in <module>
    client()
  File "/cvmfs/cms.cern.ch/crab3/slc6_amd64_gcc481/cms/crabclient/3.3.1507-comp/bin/crab", line 119, in __call__
    self.cmd = sub_cmd(self.logger, args[1:])
  File "/cvmfs/cms.cern.ch/crab3/slc6_amd64_gcc481/cms/crabclient/3.3.1507-comp/lib/python2.6/site-packages/CRABClient/Commands/SubCommand.py", line 253, in __init__
    self.validateOptions()
  File "/cvmfs/cms.cern.ch/crab3/slc6_amd64_gcc481/cms/crabclient/3.3.1507-comp/lib/python2.6/site-packages/CRABClient/Commands/status.py", line 731, in validateOptions
    SubCommand.validateOptions(self)
  File "/cvmfs/cms.cern.ch/crab3/slc6_amd64_gcc481/cms/crabclient/3.3.1507-comp/lib/python2.6/site-packages/CRABClient/Commands/SubCommand.py", line 563, in validateOptions
    raise ConfigurationException(msg)
ConfigurationException: [91mError[0m: crab3_phys14_qcd.py is not a valid CRAB project directory.
DEBUG 2015-07-19 23:31:57,137: 	 Executing command: 'status'
DEBUG 2015-07-19 23:31:57,137: 	 Found CRAB cache file /afs/cern.ch/user/h/hardenbr/.crab3
ERROR 2015-07-19 23:31:57,138: 	 Error: crab3_spring15_qcd.py is not a valid CRAB project directory.
ERROR 2015-07-19 23:31:57,138: 	 Caught exception
Traceback (most recent call last):
  File "/cvmfs/cms.cern.ch/crab3/slc6_amd64_gcc481/cms/crabclient/3.3.1507-comp/bin/crab", line 133, in <module>
    client()
  File "/cvmfs/cms.cern.ch/crab3/slc6_amd64_gcc481/cms/crabclient/3.3.1507-comp/bin/crab", line 119, in __call__
    self.cmd = sub_cmd(self.logger, args[1:])
  File "/cvmfs/cms.cern.ch/crab3/slc6_amd64_gcc481/cms/crabclient/3.3.1507-comp/lib/python2.6/site-packages/CRABClient/Commands/SubCommand.py", line 253, in __init__
    self.validateOptions()
  File "/cvmfs/cms.cern.ch/crab3/slc6_amd64_gcc481/cms/crabclient/3.3.1507-comp/lib/python2.6/site-packages/CRABClient/Commands/status.py", line 731, in validateOptions
    SubCommand.validateOptions(self)
  File "/cvmfs/cms.cern.ch/crab3/slc6_amd64_gcc481/cms/crabclient/3.3.1507-comp/lib/python2.6/site-packages/CRABClient/Commands/SubCommand.py", line 563, in validateOptions
    raise ConfigurationException(msg)
ConfigurationException: [91mError[0m: crab3_spring15_qcd.py is not a valid CRAB project directory.
DEBUG 2015-07-19 23:31:57,587: 	 Executing command: 'status'
DEBUG 2015-07-19 23:31:57,587: 	 Found CRAB cache file /afs/cern.ch/user/h/hardenbr/.crab3
ERROR 2015-07-19 23:31:57,588: 	 Error: dev.py is not a valid CRAB project directory.
ERROR 2015-07-19 23:31:57,588: 	 Caught exception
Traceback (most recent call last):
  File "/cvmfs/cms.cern.ch/crab3/slc6_amd64_gcc481/cms/crabclient/3.3.1507-comp/bin/crab", line 133, in <module>
    client()
  File "/cvmfs/cms.cern.ch/crab3/slc6_amd64_gcc481/cms/crabclient/3.3.1507-comp/bin/crab", line 119, in __call__
    self.cmd = sub_cmd(self.logger, args[1:])
  File "/cvmfs/cms.cern.ch/crab3/slc6_amd64_gcc481/cms/crabclient/3.3.1507-comp/lib/python2.6/site-packages/CRABClient/Commands/SubCommand.py", line 253, in __init__
    self.validateOptions()
  File "/cvmfs/cms.cern.ch/crab3/slc6_amd64_gcc481/cms/crabclient/3.3.1507-comp/lib/python2.6/site-packages/CRABClient/Commands/status.py", line 731, in validateOptions
    SubCommand.validateOptions(self)
  File "/cvmfs/cms.cern.ch/crab3/slc6_amd64_gcc481/cms/crabclient/3.3.1507-comp/lib/python2.6/site-packages/CRABClient/Commands/SubCommand.py", line 563, in validateOptions
    raise ConfigurationException(msg)
ConfigurationException: [91mError[0m: dev.py is not a valid CRAB project directory.
DEBUG 2015-07-19 23:31:58,032: 	 Executing command: 'status'
DEBUG 2015-07-19 23:31:58,032: 	 Found CRAB cache file /afs/cern.ch/user/h/hardenbr/.crab3
ERROR 2015-07-19 23:31:58,047: 	 Error: CfiFile_cfi.pyc is not a valid CRAB project directory.
ERROR 2015-07-19 23:31:58,047: 	 Caught exception
Traceback (most recent call last):
  File "/cvmfs/cms.cern.ch/crab3/slc6_amd64_gcc481/cms/crabclient/3.3.1507-comp/bin/crab", line 133, in <module>
    client()
  File "/cvmfs/cms.cern.ch/crab3/slc6_amd64_gcc481/cms/crabclient/3.3.1507-comp/bin/crab", line 119, in __call__
    self.cmd = sub_cmd(self.logger, args[1:])
  File "/cvmfs/cms.cern.ch/crab3/slc6_amd64_gcc481/cms/crabclient/3.3.1507-comp/lib/python2.6/site-packages/CRABClient/Commands/SubCommand.py", line 253, in __init__
    self.validateOptions()
  File "/cvmfs/cms.cern.ch/crab3/slc6_amd64_gcc481/cms/crabclient/3.3.1507-comp/lib/python2.6/site-packages/CRABClient/Commands/status.py", line 731, in validateOptions
    SubCommand.validateOptions(self)
  File "/cvmfs/cms.cern.ch/crab3/slc6_amd64_gcc481/cms/crabclient/3.3.1507-comp/lib/python2.6/site-packages/CRABClient/Commands/SubCommand.py", line 563, in validateOptions
    raise ConfigurationException(msg)
ConfigurationException: [91mError[0m: CfiFile_cfi.pyc is not a valid CRAB project directory.
DEBUG 2015-07-19 23:31:58,473: 	 Executing command: 'status'
DEBUG 2015-07-19 23:31:58,473: 	 Found CRAB cache file /afs/cern.ch/user/h/hardenbr/.crab3
ERROR 2015-07-19 23:31:58,474: 	 Error: ConfFile_cfg.pyc is not a valid CRAB project directory.
ERROR 2015-07-19 23:31:58,474: 	 Caught exception
Traceback (most recent call last):
  File "/cvmfs/cms.cern.ch/crab3/slc6_amd64_gcc481/cms/crabclient/3.3.1507-comp/bin/crab", line 133, in <module>
    client()
  File "/cvmfs/cms.cern.ch/crab3/slc6_amd64_gcc481/cms/crabclient/3.3.1507-comp/bin/crab", line 119, in __call__
    self.cmd = sub_cmd(self.logger, args[1:])
  File "/cvmfs/cms.cern.ch/crab3/slc6_amd64_gcc481/cms/crabclient/3.3.1507-comp/lib/python2.6/site-packages/CRABClient/Commands/SubCommand.py", line 253, in __init__
    self.validateOptions()
  File "/cvmfs/cms.cern.ch/crab3/slc6_amd64_gcc481/cms/crabclient/3.3.1507-comp/lib/python2.6/site-packages/CRABClient/Commands/status.py", line 731, in validateOptions
    SubCommand.validateOptions(self)
  File "/cvmfs/cms.cern.ch/crab3/slc6_amd64_gcc481/cms/crabclient/3.3.1507-comp/lib/python2.6/site-packages/CRABClient/Commands/SubCommand.py", line 563, in validateOptions
    raise ConfigurationException(msg)
ConfigurationException: [91mError[0m: ConfFile_cfg.pyc is not a valid CRAB project directory.
DEBUG 2015-07-19 23:31:58,892: 	 Executing command: 'status'
DEBUG 2015-07-19 23:31:58,892: 	 Found CRAB cache file /afs/cern.ch/user/h/hardenbr/.crab3
ERROR 2015-07-19 23:31:58,934: 	 Error: __init__.pyc is not a valid CRAB project directory.
ERROR 2015-07-19 23:31:58,935: 	 Caught exception
Traceback (most recent call last):
  File "/cvmfs/cms.cern.ch/crab3/slc6_amd64_gcc481/cms/crabclient/3.3.1507-comp/bin/crab", line 133, in <module>
    client()
  File "/cvmfs/cms.cern.ch/crab3/slc6_amd64_gcc481/cms/crabclient/3.3.1507-comp/bin/crab", line 119, in __call__
    self.cmd = sub_cmd(self.logger, args[1:])
  File "/cvmfs/cms.cern.ch/crab3/slc6_amd64_gcc481/cms/crabclient/3.3.1507-comp/lib/python2.6/site-packages/CRABClient/Commands/SubCommand.py", line 253, in __init__
    self.validateOptions()
  File "/cvmfs/cms.cern.ch/crab3/slc6_amd64_gcc481/cms/crabclient/3.3.1507-comp/lib/python2.6/site-packages/CRABClient/Commands/status.py", line 731, in validateOptions
    SubCommand.validateOptions(self)
  File "/cvmfs/cms.cern.ch/crab3/slc6_amd64_gcc481/cms/crabclient/3.3.1507-comp/lib/python2.6/site-packages/CRABClient/Commands/SubCommand.py", line 563, in validateOptions
    raise ConfigurationException(msg)
ConfigurationException: [91mError[0m: __init__.pyc is not a valid CRAB project directory.
DEBUG 2015-07-19 23:31:59,348: 	 Executing command: 'status'
DEBUG 2015-07-19 23:31:59,348: 	 Found CRAB cache file /afs/cern.ch/user/h/hardenbr/.crab3
ERROR 2015-07-19 23:31:59,349: 	 Error: analyze_cfg.pyc is not a valid CRAB project directory.
ERROR 2015-07-19 23:31:59,349: 	 Caught exception
Traceback (most recent call last):
  File "/cvmfs/cms.cern.ch/crab3/slc6_amd64_gcc481/cms/crabclient/3.3.1507-comp/bin/crab", line 133, in <module>
    client()
  File "/cvmfs/cms.cern.ch/crab3/slc6_amd64_gcc481/cms/crabclient/3.3.1507-comp/bin/crab", line 119, in __call__
    self.cmd = sub_cmd(self.logger, args[1:])
  File "/cvmfs/cms.cern.ch/crab3/slc6_amd64_gcc481/cms/crabclient/3.3.1507-comp/lib/python2.6/site-packages/CRABClient/Commands/SubCommand.py", line 253, in __init__
    self.validateOptions()
  File "/cvmfs/cms.cern.ch/crab3/slc6_amd64_gcc481/cms/crabclient/3.3.1507-comp/lib/python2.6/site-packages/CRABClient/Commands/status.py", line 731, in validateOptions
    SubCommand.validateOptions(self)
  File "/cvmfs/cms.cern.ch/crab3/slc6_amd64_gcc481/cms/crabclient/3.3.1507-comp/lib/python2.6/site-packages/CRABClient/Commands/SubCommand.py", line 563, in validateOptions
    raise ConfigurationException(msg)
ConfigurationException: [91mError[0m: analyze_cfg.pyc is not a valid CRAB project directory.
DEBUG 2015-07-19 23:31:59,761: 	 Executing command: 'status'
DEBUG 2015-07-19 23:31:59,761: 	 Found CRAB cache file /afs/cern.ch/user/h/hardenbr/.crab3
ERROR 2015-07-19 23:31:59,825: 	 Error: crab3_phys14_qcd.pyc is not a valid CRAB project directory.
ERROR 2015-07-19 23:31:59,825: 	 Caught exception
Traceback (most recent call last):
  File "/cvmfs/cms.cern.ch/crab3/slc6_amd64_gcc481/cms/crabclient/3.3.1507-comp/bin/crab", line 133, in <module>
    client()
  File "/cvmfs/cms.cern.ch/crab3/slc6_amd64_gcc481/cms/crabclient/3.3.1507-comp/bin/crab", line 119, in __call__
    self.cmd = sub_cmd(self.logger, args[1:])
  File "/cvmfs/cms.cern.ch/crab3/slc6_amd64_gcc481/cms/crabclient/3.3.1507-comp/lib/python2.6/site-packages/CRABClient/Commands/SubCommand.py", line 253, in __init__
    self.validateOptions()
  File "/cvmfs/cms.cern.ch/crab3/slc6_amd64_gcc481/cms/crabclient/3.3.1507-comp/lib/python2.6/site-packages/CRABClient/Commands/status.py", line 731, in validateOptions
    SubCommand.validateOptions(self)
  File "/cvmfs/cms.cern.ch/crab3/slc6_amd64_gcc481/cms/crabclient/3.3.1507-comp/lib/python2.6/site-packages/CRABClient/Commands/SubCommand.py", line 563, in validateOptions
    raise ConfigurationException(msg)
ConfigurationException: [91mError[0m: crab3_phys14_qcd.pyc is not a valid CRAB project directory.
DEBUG 2015-07-19 23:32:00,225: 	 Executing command: 'status'
DEBUG 2015-07-19 23:32:00,226: 	 Found CRAB cache file /afs/cern.ch/user/h/hardenbr/.crab3
ERROR 2015-07-19 23:32:00,227: 	 Error: crab3_spring15_qcd.pyc is not a valid CRAB project directory.
ERROR 2015-07-19 23:32:00,227: 	 Caught exception
Traceback (most recent call last):
  File "/cvmfs/cms.cern.ch/crab3/slc6_amd64_gcc481/cms/crabclient/3.3.1507-comp/bin/crab", line 133, in <module>
    client()
  File "/cvmfs/cms.cern.ch/crab3/slc6_amd64_gcc481/cms/crabclient/3.3.1507-comp/bin/crab", line 119, in __call__
    self.cmd = sub_cmd(self.logger, args[1:])
  File "/cvmfs/cms.cern.ch/crab3/slc6_amd64_gcc481/cms/crabclient/3.3.1507-comp/lib/python2.6/site-packages/CRABClient/Commands/SubCommand.py", line 253, in __init__
    self.validateOptions()
  File "/cvmfs/cms.cern.ch/crab3/slc6_amd64_gcc481/cms/crabclient/3.3.1507-comp/lib/python2.6/site-packages/CRABClient/Commands/status.py", line 731, in validateOptions
    SubCommand.validateOptions(self)
  File "/cvmfs/cms.cern.ch/crab3/slc6_amd64_gcc481/cms/crabclient/3.3.1507-comp/lib/python2.6/site-packages/CRABClient/Commands/SubCommand.py", line 563, in validateOptions
    raise ConfigurationException(msg)
ConfigurationException: [91mError[0m: crab3_spring15_qcd.pyc is not a valid CRAB project directory.
DEBUG 2015-07-19 23:32:00,633: 	 Executing command: 'status'
DEBUG 2015-07-19 23:32:00,633: 	 Found CRAB cache file /afs/cern.ch/user/h/hardenbr/.crab3
ERROR 2015-07-19 23:32:00,634: 	 Error: dev.pyc is not a valid CRAB project directory.
ERROR 2015-07-19 23:32:00,634: 	 Caught exception
Traceback (most recent call last):
  File "/cvmfs/cms.cern.ch/crab3/slc6_amd64_gcc481/cms/crabclient/3.3.1507-comp/bin/crab", line 133, in <module>
    client()
  File "/cvmfs/cms.cern.ch/crab3/slc6_amd64_gcc481/cms/crabclient/3.3.1507-comp/bin/crab", line 119, in __call__
    self.cmd = sub_cmd(self.logger, args[1:])
  File "/cvmfs/cms.cern.ch/crab3/slc6_amd64_gcc481/cms/crabclient/3.3.1507-comp/lib/python2.6/site-packages/CRABClient/Commands/SubCommand.py", line 253, in __init__
    self.validateOptions()
  File "/cvmfs/cms.cern.ch/crab3/slc6_amd64_gcc481/cms/crabclient/3.3.1507-comp/lib/python2.6/site-packages/CRABClient/Commands/status.py", line 731, in validateOptions
    SubCommand.validateOptions(self)
  File "/cvmfs/cms.cern.ch/crab3/slc6_amd64_gcc481/cms/crabclient/3.3.1507-comp/lib/python2.6/site-packages/CRABClient/Commands/SubCommand.py", line 563, in validateOptions
    raise ConfigurationException(msg)
ConfigurationException: [91mError[0m: dev.pyc is not a valid CRAB project directory.
DEBUG 2015-07-19 23:32:01,051: 	 Executing command: 'status'
DEBUG 2015-07-19 23:32:01,051: 	 Found CRAB cache file /afs/cern.ch/user/h/hardenbr/.crab3
ERROR 2015-07-19 23:32:01,052: 	 Error: crab3_data.py~ is not a valid CRAB project directory.
ERROR 2015-07-19 23:32:01,052: 	 Caught exception
Traceback (most recent call last):
  File "/cvmfs/cms.cern.ch/crab3/slc6_amd64_gcc481/cms/crabclient/3.3.1507-comp/bin/crab", line 133, in <module>
    client()
  File "/cvmfs/cms.cern.ch/crab3/slc6_amd64_gcc481/cms/crabclient/3.3.1507-comp/bin/crab", line 119, in __call__
    self.cmd = sub_cmd(self.logger, args[1:])
  File "/cvmfs/cms.cern.ch/crab3/slc6_amd64_gcc481/cms/crabclient/3.3.1507-comp/lib/python2.6/site-packages/CRABClient/Commands/SubCommand.py", line 253, in __init__
    self.validateOptions()
  File "/cvmfs/cms.cern.ch/crab3/slc6_amd64_gcc481/cms/crabclient/3.3.1507-comp/lib/python2.6/site-packages/CRABClient/Commands/status.py", line 731, in validateOptions
    SubCommand.validateOptions(self)
  File "/cvmfs/cms.cern.ch/crab3/slc6_amd64_gcc481/cms/crabclient/3.3.1507-comp/lib/python2.6/site-packages/CRABClient/Commands/SubCommand.py", line 563, in validateOptions
    raise ConfigurationException(msg)
ConfigurationException: [91mError[0m: crab3_data.py~ is not a valid CRAB project directory.
DEBUG 2015-07-19 23:32:01,493: 	 Executing command: 'status'
DEBUG 2015-07-19 23:32:01,493: 	 Found CRAB cache file /afs/cern.ch/user/h/hardenbr/.crab3
DEBUG 2015-07-19 23:32:01,502: 	 Checking credentials
DEBUG 2015-07-19 23:32:01,505: 	 Found proxy file /tmp/x509up_u56682
DEBUG 2015-07-19 23:32:01,505: 	 Getting proxy life time left
DEBUG 2015-07-19 23:32:02,209: 	 Executing : 
 command : voms-proxy-info -file /tmp/x509up_u56682 -timeleft
 output : 42108

 error: 
 retcode : 0
DEBUG 2015-07-19 23:32:02,719: 	 Executing : 
 command : voms-proxy-info -file /tmp/x509up_u56682 -actimeleft
 output : 42108

 error: 
 retcode : 0
DEBUG 2015-07-19 23:32:02,719: 	 Proxy valid for 11:41:48 hours
ERROR 2015-07-19 23:32:02,720: 	 Cannot find .requestcache file in CRAB project directory /afs/cern.ch/user/h/hardenbr/2014/LL_DIJET/TRACKING_STUDIES/CMSSW_7_4_6_patch2/src/DisplacedJets/DJetAnalyzer/python/CRAB3_DATA
ERROR 2015-07-19 23:32:02,720: 	 Caught exception
Traceback (most recent call last):
  File "/cvmfs/cms.cern.ch/crab3/slc6_amd64_gcc481/cms/crabclient/3.3.1507-comp/bin/crab", line 133, in <module>
    client()
  File "/cvmfs/cms.cern.ch/crab3/slc6_amd64_gcc481/cms/crabclient/3.3.1507-comp/bin/crab", line 119, in __call__
    self.cmd = sub_cmd(self.logger, args[1:])
  File "/cvmfs/cms.cern.ch/crab3/slc6_amd64_gcc481/cms/crabclient/3.3.1507-comp/lib/python2.6/site-packages/CRABClient/Commands/SubCommand.py", line 317, in __init__
    self.loadLocalCache(proxyOptsSetPlace)
  File "/cvmfs/cms.cern.ch/crab3/slc6_amd64_gcc481/cms/crabclient/3.3.1507-comp/lib/python2.6/site-packages/CRABClient/Commands/SubCommand.py", line 431, in loadLocalCache
    self.cachedinfo, self.logfile = loadCache(self.requestarea, self.logger)
  File "/cvmfs/cms.cern.ch/crab3/slc6_amd64_gcc481/cms/crabclient/3.3.1507-comp/lib/python2.6/site-packages/CRABClient/ClientUtilities.py", line 439, in loadCache
    raise CachefileNotFoundException(msg)
CachefileNotFoundException: Cannot find .requestcache file in CRAB project directory /afs/cern.ch/user/h/hardenbr/2014/LL_DIJET/TRACKING_STUDIES/CMSSW_7_4_6_patch2/src/DisplacedJets/DJetAnalyzer/python/CRAB3_DATA
DEBUG 2015-07-19 23:32:03,150: 	 Executing command: 'status'
DEBUG 2015-07-19 23:32:03,150: 	 Found CRAB cache file /afs/cern.ch/user/h/hardenbr/.crab3
ERROR 2015-07-19 23:32:03,151: 	 Error: crab3_data.py is not a valid CRAB project directory.
ERROR 2015-07-19 23:32:03,151: 	 Caught exception
Traceback (most recent call last):
  File "/cvmfs/cms.cern.ch/crab3/slc6_amd64_gcc481/cms/crabclient/3.3.1507-comp/bin/crab", line 133, in <module>
    client()
  File "/cvmfs/cms.cern.ch/crab3/slc6_amd64_gcc481/cms/crabclient/3.3.1507-comp/bin/crab", line 119, in __call__
    self.cmd = sub_cmd(self.logger, args[1:])
  File "/cvmfs/cms.cern.ch/crab3/slc6_amd64_gcc481/cms/crabclient/3.3.1507-comp/lib/python2.6/site-packages/CRABClient/Commands/SubCommand.py", line 253, in __init__
    self.validateOptions()
  File "/cvmfs/cms.cern.ch/crab3/slc6_amd64_gcc481/cms/crabclient/3.3.1507-comp/lib/python2.6/site-packages/CRABClient/Commands/status.py", line 731, in validateOptions
    SubCommand.validateOptions(self)
  File "/cvmfs/cms.cern.ch/crab3/slc6_amd64_gcc481/cms/crabclient/3.3.1507-comp/lib/python2.6/site-packages/CRABClient/Commands/SubCommand.py", line 563, in validateOptions
    raise ConfigurationException(msg)
ConfigurationException: [91mError[0m: crab3_data.py is not a valid CRAB project directory.
DEBUG 2015-07-19 23:32:03,625: 	 Executing command: 'status'
DEBUG 2015-07-19 23:32:03,625: 	 Found CRAB cache file /afs/cern.ch/user/h/hardenbr/.crab3
ERROR 2015-07-19 23:32:03,626: 	 Error: crab3_data.pyc is not a valid CRAB project directory.
ERROR 2015-07-19 23:32:03,626: 	 Caught exception
Traceback (most recent call last):
  File "/cvmfs/cms.cern.ch/crab3/slc6_amd64_gcc481/cms/crabclient/3.3.1507-comp/bin/crab", line 133, in <module>
    client()
  File "/cvmfs/cms.cern.ch/crab3/slc6_amd64_gcc481/cms/crabclient/3.3.1507-comp/bin/crab", line 119, in __call__
    self.cmd = sub_cmd(self.logger, args[1:])
  File "/cvmfs/cms.cern.ch/crab3/slc6_amd64_gcc481/cms/crabclient/3.3.1507-comp/lib/python2.6/site-packages/CRABClient/Commands/SubCommand.py", line 253, in __init__
    self.validateOptions()
  File "/cvmfs/cms.cern.ch/crab3/slc6_amd64_gcc481/cms/crabclient/3.3.1507-comp/lib/python2.6/site-packages/CRABClient/Commands/status.py", line 731, in validateOptions
    SubCommand.validateOptions(self)
  File "/cvmfs/cms.cern.ch/crab3/slc6_amd64_gcc481/cms/crabclient/3.3.1507-comp/lib/python2.6/site-packages/CRABClient/Commands/SubCommand.py", line 563, in validateOptions
    raise ConfigurationException(msg)
ConfigurationException: [91mError[0m: crab3_data.pyc is not a valid CRAB project directory.
DEBUG 2015-07-19 23:32:04,046: 	 Executing command: 'status'
DEBUG 2015-07-19 23:32:04,046: 	 Found CRAB cache file /afs/cern.ch/user/h/hardenbr/.crab3
ERROR 2015-07-19 23:32:04,046: 	 Error: run2015bAOD.txt is not a valid CRAB project directory.
ERROR 2015-07-19 23:32:04,047: 	 Caught exception
Traceback (most recent call last):
  File "/cvmfs/cms.cern.ch/crab3/slc6_amd64_gcc481/cms/crabclient/3.3.1507-comp/bin/crab", line 133, in <module>
    client()
  File "/cvmfs/cms.cern.ch/crab3/slc6_amd64_gcc481/cms/crabclient/3.3.1507-comp/bin/crab", line 119, in __call__
    self.cmd = sub_cmd(self.logger, args[1:])
  File "/cvmfs/cms.cern.ch/crab3/slc6_amd64_gcc481/cms/crabclient/3.3.1507-comp/lib/python2.6/site-packages/CRABClient/Commands/SubCommand.py", line 253, in __init__
    self.validateOptions()
  File "/cvmfs/cms.cern.ch/crab3/slc6_amd64_gcc481/cms/crabclient/3.3.1507-comp/lib/python2.6/site-packages/CRABClient/Commands/status.py", line 731, in validateOptions
    SubCommand.validateOptions(self)
  File "/cvmfs/cms.cern.ch/crab3/slc6_amd64_gcc481/cms/crabclient/3.3.1507-comp/lib/python2.6/site-packages/CRABClient/Commands/SubCommand.py", line 563, in validateOptions
    raise ConfigurationException(msg)
ConfigurationException: [91mError[0m: run2015bAOD.txt is not a valid CRAB project directory.
DEBUG 2015-07-19 23:32:04,455: 	 Executing command: 'status'
DEBUG 2015-07-19 23:32:04,456: 	 Found CRAB cache file /afs/cern.ch/user/h/hardenbr/.crab3
DEBUG 2015-07-19 23:32:04,462: 	 Checking credentials
DEBUG 2015-07-19 23:32:04,463: 	 Found proxy file /tmp/x509up_u56682
DEBUG 2015-07-19 23:32:04,463: 	 Getting proxy life time left
DEBUG 2015-07-19 23:32:04,967: 	 Executing : 
 command : voms-proxy-info -file /tmp/x509up_u56682 -timeleft
 output : 42106

 error: 
 retcode : 0
DEBUG 2015-07-19 23:32:05,472: 	 Executing : 
 command : voms-proxy-info -file /tmp/x509up_u56682 -actimeleft
 output : 42105

 error: 
 retcode : 0
DEBUG 2015-07-19 23:32:05,472: 	 Proxy valid for 11:41:46 hours
ERROR 2015-07-19 23:32:05,472: 	 Cannot find .requestcache file in CRAB project directory /afs/cern.ch/user/h/hardenbr/2014/LL_DIJET/TRACKING_STUDIES/CMSSW_7_4_6_patch2/src/DisplacedJets/DJetAnalyzer/python/CRAB3_DATA_1UNIT
ERROR 2015-07-19 23:32:05,472: 	 Caught exception
Traceback (most recent call last):
  File "/cvmfs/cms.cern.ch/crab3/slc6_amd64_gcc481/cms/crabclient/3.3.1507-comp/bin/crab", line 133, in <module>
    client()
  File "/cvmfs/cms.cern.ch/crab3/slc6_amd64_gcc481/cms/crabclient/3.3.1507-comp/bin/crab", line 119, in __call__
    self.cmd = sub_cmd(self.logger, args[1:])
  File "/cvmfs/cms.cern.ch/crab3/slc6_amd64_gcc481/cms/crabclient/3.3.1507-comp/lib/python2.6/site-packages/CRABClient/Commands/SubCommand.py", line 317, in __init__
    self.loadLocalCache(proxyOptsSetPlace)
  File "/cvmfs/cms.cern.ch/crab3/slc6_amd64_gcc481/cms/crabclient/3.3.1507-comp/lib/python2.6/site-packages/CRABClient/Commands/SubCommand.py", line 431, in loadLocalCache
    self.cachedinfo, self.logfile = loadCache(self.requestarea, self.logger)
  File "/cvmfs/cms.cern.ch/crab3/slc6_amd64_gcc481/cms/crabclient/3.3.1507-comp/lib/python2.6/site-packages/CRABClient/ClientUtilities.py", line 439, in loadCache
    raise CachefileNotFoundException(msg)
CachefileNotFoundException: Cannot find .requestcache file in CRAB project directory /afs/cern.ch/user/h/hardenbr/2014/LL_DIJET/TRACKING_STUDIES/CMSSW_7_4_6_patch2/src/DisplacedJets/DJetAnalyzer/python/CRAB3_DATA_1UNIT
DEBUG 2015-07-19 23:32:05,900: 	 Executing command: 'status'
DEBUG 2015-07-19 23:32:05,900: 	 Found CRAB cache file /afs/cern.ch/user/h/hardenbr/.crab3
ERROR 2015-07-19 23:32:05,901: 	 Error: Cert_246908-251252_13TeV_PromptReco_Collisions15_JSON.txt is not a valid CRAB project directory.
ERROR 2015-07-19 23:32:05,901: 	 Caught exception
Traceback (most recent call last):
  File "/cvmfs/cms.cern.ch/crab3/slc6_amd64_gcc481/cms/crabclient/3.3.1507-comp/bin/crab", line 133, in <module>
    client()
  File "/cvmfs/cms.cern.ch/crab3/slc6_amd64_gcc481/cms/crabclient/3.3.1507-comp/bin/crab", line 119, in __call__
    self.cmd = sub_cmd(self.logger, args[1:])
  File "/cvmfs/cms.cern.ch/crab3/slc6_amd64_gcc481/cms/crabclient/3.3.1507-comp/lib/python2.6/site-packages/CRABClient/Commands/SubCommand.py", line 253, in __init__
    self.validateOptions()
  File "/cvmfs/cms.cern.ch/crab3/slc6_amd64_gcc481/cms/crabclient/3.3.1507-comp/lib/python2.6/site-packages/CRABClient/Commands/status.py", line 731, in validateOptions
    SubCommand.validateOptions(self)
  File "/cvmfs/cms.cern.ch/crab3/slc6_amd64_gcc481/cms/crabclient/3.3.1507-comp/lib/python2.6/site-packages/CRABClient/Commands/SubCommand.py", line 563, in validateOptions
    raise ConfigurationException(msg)
ConfigurationException: [91mError[0m: Cert_246908-251252_13TeV_PromptReco_Collisions15_JSON.txt is not a valid CRAB project directory.
DEBUG 2015-07-19 23:32:06,416: 	 Executing command: 'status'
DEBUG 2015-07-19 23:32:06,416: 	 Found CRAB cache file /afs/cern.ch/user/h/hardenbr/.crab3
DEBUG 2015-07-19 23:32:06,423: 	 Checking credentials
DEBUG 2015-07-19 23:32:06,423: 	 Found proxy file /tmp/x509up_u56682
DEBUG 2015-07-19 23:32:06,423: 	 Getting proxy life time left
DEBUG 2015-07-19 23:32:06,928: 	 Executing : 
 command : voms-proxy-info -file /tmp/x509up_u56682 -timeleft
 output : 42104

 error: 
 retcode : 0
DEBUG 2015-07-19 23:32:07,434: 	 Executing : 
 command : voms-proxy-info -file /tmp/x509up_u56682 -actimeleft
 output : 42103

 error: 
 retcode : 0
DEBUG 2015-07-19 23:32:07,435: 	 Proxy valid for 11:41:44 hours
ERROR 2015-07-19 23:32:07,435: 	 Cannot find .requestcache file in CRAB project directory /afs/cern.ch/user/h/hardenbr/2014/LL_DIJET/TRACKING_STUDIES/CMSSW_7_4_6_patch2/src/DisplacedJets/DJetAnalyzer/python/CRAB3_DATA_4LUMIS
ERROR 2015-07-19 23:32:07,435: 	 Caught exception
Traceback (most recent call last):
  File "/cvmfs/cms.cern.ch/crab3/slc6_amd64_gcc481/cms/crabclient/3.3.1507-comp/bin/crab", line 133, in <module>
    client()
  File "/cvmfs/cms.cern.ch/crab3/slc6_amd64_gcc481/cms/crabclient/3.3.1507-comp/bin/crab", line 119, in __call__
    self.cmd = sub_cmd(self.logger, args[1:])
  File "/cvmfs/cms.cern.ch/crab3/slc6_amd64_gcc481/cms/crabclient/3.3.1507-comp/lib/python2.6/site-packages/CRABClient/Commands/SubCommand.py", line 317, in __init__
    self.loadLocalCache(proxyOptsSetPlace)
  File "/cvmfs/cms.cern.ch/crab3/slc6_amd64_gcc481/cms/crabclient/3.3.1507-comp/lib/python2.6/site-packages/CRABClient/Commands/SubCommand.py", line 431, in loadLocalCache
    self.cachedinfo, self.logfile = loadCache(self.requestarea, self.logger)
  File "/cvmfs/cms.cern.ch/crab3/slc6_amd64_gcc481/cms/crabclient/3.3.1507-comp/lib/python2.6/site-packages/CRABClient/ClientUtilities.py", line 439, in loadCache
    raise CachefileNotFoundException(msg)
CachefileNotFoundException: Cannot find .requestcache file in CRAB project directory /afs/cern.ch/user/h/hardenbr/2014/LL_DIJET/TRACKING_STUDIES/CMSSW_7_4_6_patch2/src/DisplacedJets/DJetAnalyzer/python/CRAB3_DATA_4LUMIS
DEBUG 2015-07-19 23:32:07,844: 	 Executing command: 'status'
DEBUG 2015-07-19 23:32:07,844: 	 Found CRAB cache file /afs/cern.ch/user/h/hardenbr/.crab3
ERROR 2015-07-19 23:32:07,844: 	 Error: run2015bAOD.txt~ is not a valid CRAB project directory.
ERROR 2015-07-19 23:32:07,844: 	 Caught exception
Traceback (most recent call last):
  File "/cvmfs/cms.cern.ch/crab3/slc6_amd64_gcc481/cms/crabclient/3.3.1507-comp/bin/crab", line 133, in <module>
    client()
  File "/cvmfs/cms.cern.ch/crab3/slc6_amd64_gcc481/cms/crabclient/3.3.1507-comp/bin/crab", line 119, in __call__
    self.cmd = sub_cmd(self.logger, args[1:])
  File "/cvmfs/cms.cern.ch/crab3/slc6_amd64_gcc481/cms/crabclient/3.3.1507-comp/lib/python2.6/site-packages/CRABClient/Commands/SubCommand.py", line 253, in __init__
    self.validateOptions()
  File "/cvmfs/cms.cern.ch/crab3/slc6_amd64_gcc481/cms/crabclient/3.3.1507-comp/lib/python2.6/site-packages/CRABClient/Commands/status.py", line 731, in validateOptions
    SubCommand.validateOptions(self)
  File "/cvmfs/cms.cern.ch/crab3/slc6_amd64_gcc481/cms/crabclient/3.3.1507-comp/lib/python2.6/site-packages/CRABClient/Commands/SubCommand.py", line 563, in validateOptions
    raise ConfigurationException(msg)
ConfigurationException: [91mError[0m: run2015bAOD.txt~ is not a valid CRAB project directory.
DEBUG 2015-07-19 23:32:08,274: 	 Executing command: 'status'
DEBUG 2015-07-19 23:32:08,274: 	 Found CRAB cache file /afs/cern.ch/user/h/hardenbr/.crab3
DEBUG 2015-07-19 23:32:08,281: 	 Checking credentials
DEBUG 2015-07-19 23:32:08,281: 	 Found proxy file /tmp/x509up_u56682
DEBUG 2015-07-19 23:32:08,281: 	 Getting proxy life time left
DEBUG 2015-07-19 23:32:08,785: 	 Executing : 
 command : voms-proxy-info -file /tmp/x509up_u56682 -timeleft
 output : 42102

 error: 
 retcode : 0
DEBUG 2015-07-19 23:32:09,391: 	 Executing : 
 command : voms-proxy-info -file /tmp/x509up_u56682 -actimeleft
 output : 42101

 error: 
 retcode : 0
DEBUG 2015-07-19 23:32:09,392: 	 Proxy valid for 11:41:42 hours
ERROR 2015-07-19 23:32:09,392: 	 Cannot find .requestcache file in CRAB project directory /afs/cern.ch/user/h/hardenbr/2014/LL_DIJET/TRACKING_STUDIES/CMSSW_7_4_6_patch2/src/DisplacedJets/DJetAnalyzer/python/CRAB3_DATA_4LUMIS_v3
ERROR 2015-07-19 23:32:09,392: 	 Caught exception
Traceback (most recent call last):
  File "/cvmfs/cms.cern.ch/crab3/slc6_amd64_gcc481/cms/crabclient/3.3.1507-comp/bin/crab", line 133, in <module>
    client()
  File "/cvmfs/cms.cern.ch/crab3/slc6_amd64_gcc481/cms/crabclient/3.3.1507-comp/bin/crab", line 119, in __call__
    self.cmd = sub_cmd(self.logger, args[1:])
  File "/cvmfs/cms.cern.ch/crab3/slc6_amd64_gcc481/cms/crabclient/3.3.1507-comp/lib/python2.6/site-packages/CRABClient/Commands/SubCommand.py", line 317, in __init__
    self.loadLocalCache(proxyOptsSetPlace)
  File "/cvmfs/cms.cern.ch/crab3/slc6_amd64_gcc481/cms/crabclient/3.3.1507-comp/lib/python2.6/site-packages/CRABClient/Commands/SubCommand.py", line 431, in loadLocalCache
    self.cachedinfo, self.logfile = loadCache(self.requestarea, self.logger)
  File "/cvmfs/cms.cern.ch/crab3/slc6_amd64_gcc481/cms/crabclient/3.3.1507-comp/lib/python2.6/site-packages/CRABClient/ClientUtilities.py", line 439, in loadCache
    raise CachefileNotFoundException(msg)
CachefileNotFoundException: Cannot find .requestcache file in CRAB project directory /afs/cern.ch/user/h/hardenbr/2014/LL_DIJET/TRACKING_STUDIES/CMSSW_7_4_6_patch2/src/DisplacedJets/DJetAnalyzer/python/CRAB3_DATA_4LUMIS_v3
